<?xml version="1.0" encoding="utf-8"?>
<!-- This URDF was automatically created by SolidWorks to URDF Exporter! Originally created by Stephen Brawner (brawner@gmail.com) 
     Commit Version: 1.6.0-4-g7f85cfe  Build Version: 1.6.7995.38578
     For more information, please see http://wiki.ros.org/sw_urdf_exporter -->
<robot
  name="mobile_platform_gen3_wide_wheel_urdf">

<link name="dummy">
  </link>

  <link
    name="base_link">
    <inertial>
      <origin
        xyz="0.0 0.0 0.061298696891405"
        rpy="0 0 0" />
      <mass
        value="4.5" />
      <inertia
        ixx="0.0225456696225423"
        ixy="-1.84020714024046E-05"
        ixz="-0.00187225282049763"
        iyy="0.0465437023707633"
        iyz="5.4063546445361E-06"
        izz="0.0590771369694188" />
    </inertial>
    <visual>
      <origin
        xyz="0 0 0"
        rpy="0 0 0" />
      <geometry>
        <mesh
          filename="package://mobile_platform_gen3_wide_wheel_urdf/meshes/base_link.STL" />
      </geometry>
      <material
        name="">
        <color
          rgba="0.752941176470588 0.752941176470588 0.752941176470588 1" />
      </material>
    </visual>
    <collision>
      <origin
        xyz="0 0 0"
        rpy="0 0 0" />
      <geometry>
        <mesh
          filename="package://mobile_platform_gen3_wide_wheel_urdf/meshes/base_link.STL" />
      </geometry>
    </collision>
  </link>

<joint name="dummy_joint" type="fixed">
   <parent link="dummy"/>
   <child link="base_link"/>
 </joint>

  <link
    name="LF2_Link">
    <inertial>
      <origin
        xyz="0.000177066941838055 0.00238059348160047 3.04718962471084E-06"
        rpy="0 0 0" />
      <mass
        value="0.8" />
      <inertia
        ixx="0.00020503259875413"
        ixy="6.75864332395974E-07"
        ixz="-3.68818359075002E-07"
        iyy="0.000299541738357316"
        iyz="-1.72473812530403E-07"
        izz="0.000151339897550825" />
    </inertial>
    <visual>
      <origin
        xyz="0 0 0"
        rpy="0 0 0" />
      <geometry>
        <mesh
          filename="package://mobile_platform_gen3_wide_wheel_urdf/meshes/LF2_Link.STL" />
      </geometry>
      <material
        name="">
        <color
          rgba="0.752941176470588 0.752941176470588 0.752941176470588 1" />
      </material>
    </visual>
    <collision>
      <origin
        xyz="0 0 0"
        rpy="0 0 0" />
      <geometry>
        <mesh
          filename="package://mobile_platform_gen3_wide_wheel_urdf/meshes/LF2_Link.STL" />
      </geometry>
    </collision>
  </link>
  <joint
    name="LF2_Joint"
    type="continuous">
    <origin
      xyz="0.194999999999995 0.138499999999992 0.052500000000003"
      rpy="0 0 0" />
    <parent
      link="base_link" />
    <child
      link="LF2_Link" />
    <axis
      xyz="0 0 1" />
  </joint>
  <link
    name="LF1_Link">
    <inertial>
      <origin
        xyz="-0.0318468820872356 0.0302764822704568 0.000147529294126453"
        rpy="0 0 0" />
      <mass
        value="0.8" />
      <inertia
        ixx="0.000337467149402487"
        ixy="0.000152358661677688"
        ixz="1.42010516657995E-06"
        iyy="0.000460807932668524"
        iyz="1.79133753723983E-08"
        izz="0.000506700151713982" />
    </inertial>
    <visual>
      <origin
        xyz="0 0 0"
        rpy="0 0 0" />
      <geometry>
        <mesh
          filename="package://mobile_platform_gen3_wide_wheel_urdf/meshes/LF1_Link.STL" />
      </geometry>
      <material
        name="">
        <color
          rgba="0.752941176470588 0.752941176470588 0.752941176470588 1" />
      </material>
    </visual>
    <collision>
      <origin
        xyz="0 0 0"
        rpy="0 0 0" />
      <geometry>
        <mesh
          filename="package://mobile_platform_gen3_wide_wheel_urdf/meshes/LF1_Link.STL" />
      </geometry>
    </collision>
  </link>
  <joint
    name="LF1_Joint"
    type="fixed">
    <origin
      xyz="0 0.00675000000000026 0"
      rpy="0 0 0" />
    <parent
      link="LF2_Link" />
    <child
      link="LF1_Link" />
    <axis
      xyz="0 1 0" />
  </joint>
  <link
    name="LF0_Link">
    <inertial>
      <origin
        xyz="0.000239426478726323 0.000570289922476541 5.29985645396913E-05"
        rpy="0 0 0" />
      <mass
        value="2.2" />
      <inertia
        ixx="0.00938753913695465"
        ixy="2.87272138380677E-07"
        ixz="7.34561507713243E-06"
        iyy="0.0178557390232477"
        iyz="6.35347159765153E-08"
        izz="0.00936044451327353" />
    </inertial>
    <visual>
      <origin
        xyz="0 0 0"
        rpy="0 0 0" />
      <geometry>
        <mesh
          filename="package://mobile_platform_gen3_wide_wheel_urdf/meshes/LF0_Link.STL" />
      </geometry>
      <material
        name="">
        <color
          rgba="1 1 1 1" />
      </material>
    </visual>
    <collision>
      <origin
        xyz="0 0 0"
        rpy="0 0 0" />
      <geometry>
        <mesh
          filename="package://mobile_platform_gen3_wide_wheel_urdf/meshes/LF0_Link.STL" />
      </geometry>
    </collision>
  </link>
  <joint
    name="LF0_Joint"
    type="continuous">
    <origin
      xyz="-0.0500000000000006 0.0651499999999992 0"
      rpy="0 0 0" />
    <parent
      link="LF1_Link" />
    <child
      link="LF0_Link" />
    <axis
      xyz="0 -1 0" />
  </joint>
  <link
    name="RF2_Link">
    <inertial>
      <origin
        xyz="0.000177066941837833 -0.00238059348159969 3.04718962654271E-06"
        rpy="0 0 0" />
      <mass
        value="0.8" />
      <inertia
        ixx="0.000205032598754135"
        ixy="-6.75864332395546E-07"
        ixz="-3.68818359075823E-07"
        iyy="0.000299541738357322"
        iyz="1.72473812528975E-07"
        izz="0.000151339897550824" />
    </inertial>
    <visual>
      <origin
        xyz="0 0 0"
        rpy="0 0 0" />
      <geometry>
        <mesh
          filename="package://mobile_platform_gen3_wide_wheel_urdf/meshes/RF2_Link.STL" />
      </geometry>
      <material
        name="">
        <color
          rgba="0.752941176470588 0.752941176470588 0.752941176470588 1" />
      </material>
    </visual>
    <collision>
      <origin
        xyz="0 0 0"
        rpy="0 0 0" />
      <geometry>
        <mesh
          filename="package://mobile_platform_gen3_wide_wheel_urdf/meshes/RF2_Link.STL" />
      </geometry>
    </collision>
  </link>
  <joint
    name="RF2_Joint"
    type="continuous">
    <origin
      xyz="0.194999999999998 -0.138500000000007 0.0524999999999921"
      rpy="0 0 0" />
    <parent
      link="base_link" />
    <child
      link="RF2_Link" />
    <axis
      xyz="0 0 1" />
  </joint>
  <link
    name="RF1_Link">
    <inertial>
      <origin
        xyz="-0.0319690993561761 -0.0302764822704572 0.00014752929613715"
        rpy="0 0 0" />
      <mass
        value="0.8" />
      <inertia
        ixx="0.00033750699567887"
        ixy="-0.000152343821751643"
        ixz="1.8504488511453E-07"
        iyy="0.00046209834303011"
        iyz="-1.79133657870878E-08"
        izz="0.000507950715799196" />
    </inertial>
    <visual>
      <origin
        xyz="0 0 0"
        rpy="0 0 0" />
      <geometry>
        <mesh
          filename="package://mobile_platform_gen3_wide_wheel_urdf/meshes/RF1_Link.STL" />
      </geometry>
      <material
        name="">
        <color
          rgba="0.752941176470588 0.752941176470588 0.752941176470588 1" />
      </material>
    </visual>
    <collision>
      <origin
        xyz="0 0 0"
        rpy="0 0 0" />
      <geometry>
        <mesh
          filename="package://mobile_platform_gen3_wide_wheel_urdf/meshes/RF1_Link.STL" />
      </geometry>
    </collision>
  </link>
  <joint
    name="RF1_Joint"
    type="fixed">
    <origin
      xyz="0 -0.00674999999999853 0"
      rpy="0 0 0" />
    <parent
      link="RF2_Link" />
    <child
      link="RF1_Link" />
    <axis
      xyz="0 -1 0" />
  </joint>
  <link
    name="RF0_Link">
    <inertial>
      <origin
        xyz="0.000104421717959102 -0.000570289922476513 -0.000221874353472706"
        rpy="0 0 0" />
      <mass
        value="2.2" />
      <inertia
        ixx="0.00936491509548454"
        ixy="-1.24865635649255E-07"
        ixz="-1.24528598441868E-05"
        iyy="0.0178557390269462"
        iyz="2.66271960673673E-07"
        izz="0.0093830685584422" />
    </inertial>
    <visual>
      <origin
        xyz="0 0 0"
        rpy="0 0 0" />
      <geometry>
        <mesh
          filename="package://mobile_platform_gen3_wide_wheel_urdf/meshes/RF0_Link.STL" />
      </geometry>
      <material
        name="">
        <color
          rgba="1 1 1 1" />
      </material>
    </visual>
    <collision>
      <origin
        xyz="0 0 0"
        rpy="0 0 0" />
      <geometry>
        <mesh
          filename="package://mobile_platform_gen3_wide_wheel_urdf/meshes/RF0_Link.STL" />
      </geometry>
    </collision>
  </link>
  <joint
    name="RF0_Joint"
    type="continuous">
    <origin
      xyz="-0.049999999999999 -0.0651499999999996 0"
      rpy="0 0 0" />
    <parent
      link="RF1_Link" />
    <child
      link="RF0_Link" />
    <axis
      xyz="0 -1 0" />
  </joint>
  <link
    name="LB2_Link">
    <inertial>
      <origin
        xyz="0.000177066941837223 0.00238059348159969 3.0471896256129E-06"
        rpy="0 0 0" />
      <mass
        value="0.8" />
      <inertia
        ixx="0.000205032598754128"
        ixy="6.75864332395181E-07"
        ixz="-3.68818359076586E-07"
        iyy="0.000299541738357316"
        iyz="-1.72473812524931E-07"
        izz="0.000151339897550823" />
    </inertial>
    <visual>
      <origin
        xyz="0 0 0"
        rpy="0 0 0" />
      <geometry>
        <mesh
          filename="package://mobile_platform_gen3_wide_wheel_urdf/meshes/LB2_Link.STL" />
      </geometry>
      <material
        name="">
        <color
          rgba="0.752941176470588 0.752941176470588 0.752941176470588 1" />
      </material>
    </visual>
    <collision>
      <origin
        xyz="0 0 0"
        rpy="0 0 0" />
      <geometry>
        <mesh
          filename="package://mobile_platform_gen3_wide_wheel_urdf/meshes/LB2_Link.STL" />
      </geometry>
    </collision>
  </link>
  <joint
    name="LB2_Joint"
    type="continuous">
    <origin
      xyz="-0.195000000000005 0.138499999999994 0.052500000000003"
      rpy="0 0 0" />
    <parent
      link="base_link" />
    <child
      link="LB2_Link" />
    <axis
      xyz="0 0 1" />
  </joint>
  <link
    name="LB1_Link">
    <inertial>
      <origin
        xyz="0.0320555200158374 0.0302764822704571 6.11086348523415E-05"
        rpy="0 0 0" />
      <mass
        value="0.8" />
      <inertia
        ixx="0.000338709235668273"
        ixy="-0.000152333328339301"
        ixz="2.78210055809599E-07"
        iyy="0.000463010800947307"
        iyz="7.41996123234184E-09"
        izz="0.000507660933726987" />
    </inertial>
    <visual>
      <origin
        xyz="0 0 0"
        rpy="0 0 0" />
      <geometry>
        <mesh
          filename="package://mobile_platform_gen3_wide_wheel_urdf/meshes/LB1_Link.STL" />
      </geometry>
      <material
        name="">
        <color
          rgba="0.752941176470588 0.752941176470588 0.752941176470588 1" />
      </material>
    </visual>
    <collision>
      <origin
        xyz="0 0 0"
        rpy="0 0 0" />
      <geometry>
        <mesh
          filename="package://mobile_platform_gen3_wide_wheel_urdf/meshes/LB1_Link.STL" />
      </geometry>
    </collision>
  </link>
  <joint
    name="LB1_Joint"
    type="fixed">
    <origin
      xyz="0 0.00674999999999559 0"
      rpy="0 0 0" />
    <parent
      link="LB2_Link" />
    <child
      link="LB1_Link" />
    <axis
      xyz="0 1 0" />
  </joint>
  <link
    name="LB0_Link">
    <inertial>
      <origin
        xyz="-1.50281773816374E-05 0.00057028992247643 0.000244761190639209"
        rpy="0 0 0" />
      <mass
        value="2.2" />
      <inertia
        ixx="0.00935884078197502"
        ixy="-1.79772069266924E-08"
        ixz="-2.81666660519736E-06"
        iyy="0.0178557390232477"
        iyz="2.93664369204658E-07"
        izz="0.00938914286825317" />
    </inertial>
    <visual>
      <origin
        xyz="0 0 0"
        rpy="0 0 0" />
      <geometry>
        <mesh
          filename="package://mobile_platform_gen3_wide_wheel_urdf/meshes/LB0_Link.STL" />
      </geometry>
      <material
        name="">
        <color
          rgba="1 1 1 1" />
      </material>
    </visual>
    <collision>
      <origin
        xyz="0 0 0"
        rpy="0 0 0" />
      <geometry>
        <mesh
          filename="package://mobile_platform_gen3_wide_wheel_urdf/meshes/LB0_Link.STL" />
      </geometry>
    </collision>
  </link>
  <joint
    name="LB0_Joint"
    type="continuous">
    <origin
      xyz="0.0499999999999848 0.0651500000000003 0"
      rpy="0 0 0" />
    <parent
      link="LB1_Link" />
    <child
      link="LB0_Link" />
    <axis
      xyz="0 -1 0" />
  </joint>
  <link
    name="RB2_Link">
    <inertial>
      <origin
        xyz="0.000177066941838055 -0.00238059348160075 3.04718962634842E-06"
        rpy="0 0 0" />
      <mass
        value="0.8" />
      <inertia
        ixx="0.000205032598754131"
        ixy="-6.75864332395567E-07"
        ixz="-3.68818359076196E-07"
        iyy="0.000299541738357316"
        iyz="1.72473812528444E-07"
        izz="0.000151339897550825" />
    </inertial>
    <visual>
      <origin
        xyz="0 0 0"
        rpy="0 0 0" />
      <geometry>
        <mesh
          filename="package://mobile_platform_gen3_wide_wheel_urdf/meshes/RB2_Link.STL" />
      </geometry>
      <material
        name="">
        <color
          rgba="0.752941176470588 0.752941176470588 0.752941176470588 1" />
      </material>
    </visual>
    <collision>
      <origin
        xyz="0 0 0"
        rpy="0 0 0" />
      <geometry>
        <mesh
          filename="package://mobile_platform_gen3_wide_wheel_urdf/meshes/RB2_Link.STL" />
      </geometry>
    </collision>
  </link>
  <joint
    name="RB2_Joint"
    type="continuous">
    <origin
      xyz="-0.195000000000003 -0.138500000000004 0.0524999999999989"
      rpy="0 0 0" />
    <parent
      link="base_link" />
    <child
      link="RB2_Link" />
    <axis
      xyz="0 0 1" />
  </joint>
  <link
    name="RB1_Link">
    <inertial>
      <origin
        xyz="0.0319690993561799 -0.0302764822704568 0.000147529295422125"
        rpy="0 0 0" />
      <mass
        value="0.8" />
      <inertia
        ixx="0.000337460123428899"
        ixy="0.000152343821751641"
        ixz="-1.38172631351558E-07"
        iyy="0.000462098343030115"
        iyz="-1.79133691940941E-08"
        izz="0.000507997588049165" />
    </inertial>
    <visual>
      <origin
        xyz="0 0 0"
        rpy="0 0 0" />
      <geometry>
        <mesh
          filename="package://mobile_platform_gen3_wide_wheel_urdf/meshes/RB1_Link.STL" />
      </geometry>
      <material
        name="">
        <color
          rgba="0.752941176470588 0.752941176470588 0.752941176470588 1" />
      </material>
    </visual>
    <collision>
      <origin
        xyz="0 0 0"
        rpy="0 0 0" />
      <geometry>
        <mesh
          filename="package://mobile_platform_gen3_wide_wheel_urdf/meshes/RB1_Link.STL" />
      </geometry>
    </collision>
  </link>
  <joint
    name="RB1_Joint"
    type="fixed">
    <origin
      xyz="0 -0.0067500000000052 0"
      rpy="0 0 0" />
    <parent
      link="RB2_Link" />
    <child
      link="RB1_Link" />
    <axis
      xyz="0 -1 0" />
  </joint>
  <link
    name="RB0_Link">
    <inertial>
      <origin
        xyz="0.000197003380173144 -0.000570289922476375 -0.000146025870169805"
        rpy="0 0 0" />
      <mass
        value="2.2" />
      <inertia
        ixx="0.00937756355724757"
        ixy="-2.3639378475433E-07"
        ixz="-1.4991012258464E-05"
        iyy="0.0178557390232476"
        iyz="1.75156844678005E-07"
        izz="0.00937042009298058" />
    </inertial>
    <visual>
      <origin
        xyz="0 0 0"
        rpy="0 0 0" />
      <geometry>
        <mesh
          filename="package://mobile_platform_gen3_wide_wheel_urdf/meshes/RB0_Link.STL" />
      </geometry>
      <material
        name="">
        <color
          rgba="1 1 1 1" />
      </material>
    </visual>
    <collision>
      <origin
        xyz="0 0 0"
        rpy="0 0 0" />
      <geometry>
        <mesh
          filename="package://mobile_platform_gen3_wide_wheel_urdf/meshes/RB0_Link.STL" />
      </geometry>
    </collision>
  </link>
  <joint
    name="RB0_Joint"
    type="continuous">
    <origin
      xyz="0.0500000000000009 -0.0651499999999994 0"
      rpy="0 0 0" />
    <parent
      link="RB1_Link" />
    <child
      link="RB0_Link" />
    <axis
      xyz="0 -1 0" />
  </joint>

<!-- 以下为手动添加部分 -->
<!-- 除此以下部分之外,还添加了dummy,修改了各关节(joint)的axis,各构件(link)的mass,base_link质心 -->
<!-- 物理参数 -->
<gazebo reference="base_link">
    <material>Gazebo/White</material>
</gazebo>
<gazebo reference="LF0_Link">
    <mu1>2.5</mu1>
    <mu2>2.5</mu2>
    <material>Gazebo/Red</material>
</gazebo>
<gazebo reference="RF0_Link">
    <mu1>2.5</mu1>
    <mu2>2.5</mu2>
    <material>Gazebo/Red</material>
</gazebo>
<gazebo reference="LB0_Link">
    <mu1>2.5</mu1>
    <mu2>2.5</mu2>
    <material>Gazebo/Red</material>
</gazebo>
<gazebo reference="RB0_Link">
    <mu1>2.5</mu1>
    <mu2>2.5</mu2>
    <material>Gazebo/Red</material>
</gazebo>
<gazebo reference="LF1_Link">
    <material>Gazebo/Green</material>
</gazebo>
<gazebo reference="RF1_Link">
    <material>Gazebo/Green</material>
</gazebo>
<gazebo reference="LB1_Link">
    <material>Gazebo/Green</material>
</gazebo>
<gazebo reference="RB1_Link">
    <material>Gazebo/Green</material>
</gazebo>
<gazebo reference="LF2_Link">
    <material>Gazebo/Blue</material>
</gazebo>
<gazebo reference="RF2_Link">
    <material>Gazebo/Blue</material>
</gazebo>
<gazebo reference="LB2_Link">
    <material>Gazebo/Blue</material>
</gazebo>
<gazebo reference="RB2_Link">
    <material>Gazebo/Blue</material>
</gazebo>


<!-- 控制器 -->
<gazebo>
<plugin filename="libgazebo_ros_control.so" name="gazebo_ros_control">
<robotNamespace>/</robotNamespace>
<robotSimType>gazebo_ros_control/DefaultRobotHWSim</robotSimType>
<legacyModeNS>true</legacyModeNS>
</plugin>
</gazebo>

<!-- 链接器 -->
<transmission name="LF0_Trans">
<type>transmission_interface/SimpleTransmission</type>
<joint name="LF0_Joint">
<hardwareInterface>hardware_interface/EffortJointInterface</hardwareInterface>
</joint>
<actuator name="LF0_Motor">
<hardwareInterface>hardware_interface/EffortJointInterface</hardwareInterface>
<mechanicalReduction>1</mechanicalReduction>
</actuator>
</transmission>

<transmission name="RF0_Trans">
<type>transmission_interface/SimpleTransmission</type>
<joint name="RF0_Joint">
<hardwareInterface>hardware_interface/EffortJointInterface</hardwareInterface>
</joint>
<actuator name="RF0_Motor">
<hardwareInterface>hardware_interface/EffortJointInterface</hardwareInterface>
<mechanicalReduction>1</mechanicalReduction>
</actuator>
</transmission>

<transmission name="LB0_Trans">
<type>transmission_interface/SimpleTransmission</type>
<joint name="LB0_Joint">
<hardwareInterface>hardware_interface/EffortJointInterface</hardwareInterface>
</joint>
<actuator name="LB0_Motor">
<hardwareInterface>hardware_interface/EffortJointInterface</hardwareInterface>
<mechanicalReduction>1</mechanicalReduction>
</actuator>
</transmission>

<transmission name="RB0_Trans">
<type>transmission_interface/SimpleTransmission</type>
<joint name="RB0_Joint">
<hardwareInterface>hardware_interface/EffortJointInterface</hardwareInterface>
</joint>
<actuator name="RB0_Motor">
<hardwareInterface>hardware_interface/EffortJointInterface</hardwareInterface>
<mechanicalReduction>1</mechanicalReduction>
</actuator>
</transmission>

<!-- <transmission name="LF1_Trans">
<type>transmission_interface/SimpleTransmission</type>
<joint name="LF1_Joint">
<hardwareInterface>hardware_interface/EffortJointInterface</hardwareInterface>
</joint>
<actuator name="LF1_Motor">
<hardwareInterface>hardware_interface/EffortJointInterface</hardwareInterface>
<mechanicalReduction>1</mechanicalReduction>
</actuator>
</transmission>

<transmission name="RF1_Trans">
<type>transmission_interface/SimpleTransmission</type>
<joint name="RF1_Joint">
<hardwareInterface>hardware_interface/EffortJointInterface</hardwareInterface>
</joint>
<actuator name="RF1_Motor">
<hardwareInterface>hardware_interface/EffortJointInterface</hardwareInterface>
<mechanicalReduction>1</mechanicalReduction>
</actuator>
</transmission>

<transmission name="LB1_Trans">
<type>transmission_interface/SimpleTransmission</type>
<joint name="LB1_Joint">
<hardwareInterface>hardware_interface/EffortJointInterface</hardwareInterface>
</joint>
<actuator name="LB1_Motor">
<hardwareInterface>hardware_interface/EffortJointInterface</hardwareInterface>
<mechanicalReduction>1</mechanicalReduction>
</actuator>
</transmission>

<transmission name="RB1_Trans">
<type>transmission_interface/SimpleTransmission</type>
<joint name="RB1_Joint">
<hardwareInterface>hardware_interface/EffortJointInterface</hardwareInterface>
</joint>
<actuator name="RB1_Motor">
<hardwareInterface>hardware_interface/EffortJointInterface</hardwareInterface>
<mechanicalReduction>1</mechanicalReduction>
</actuator>
</transmission> -->

<transmission name="LF2_Trans">
<type>transmission_interface/SimpleTransmission</type>
<joint name="LF2_Joint">
<hardwareInterface>hardware_interface/EffortJointInterface</hardwareInterface>
</joint>
<actuator name="LF2_Motor">
<hardwareInterface>hardware_interface/EffortJointInterface</hardwareInterface>
<mechanicalReduction>1</mechanicalReduction>
</actuator>
</transmission>

<transmission name="RF2_Trans">
<type>transmission_interface/SimpleTransmission</type>
<joint name="RF2_Joint">
<hardwareInterface>hardware_interface/EffortJointInterface</hardwareInterface>
</joint>
<actuator name="RF2_Motor">
<hardwareInterface>hardware_interface/EffortJointInterface</hardwareInterface>
<mechanicalReduction>1</mechanicalReduction>
</actuator>
</transmission>

<transmission name="LB2_Trans">
<type>transmission_interface/SimpleTransmission</type>
<joint name="LB2_Joint">
<hardwareInterface>hardware_interface/EffortJointInterface</hardwareInterface>
</joint>
<actuator name="LB2_Motor">
<hardwareInterface>hardware_interface/EffortJointInterface</hardwareInterface>
<mechanicalReduction>1</mechanicalReduction>
</actuator>
</transmission>

<transmission name="RB2_Trans">
<type>transmission_interface/SimpleTransmission</type>
<joint name="RB2_Joint">
<hardwareInterface>hardware_interface/EffortJointInterface</hardwareInterface>
</joint>
<actuator name="RB2_Motor">
<hardwareInterface>hardware_interface/EffortJointInterface</hardwareInterface>
<mechanicalReduction>1</mechanicalReduction>
</actuator>
</transmission>

</robot>
